// const CatchAsyncError = (theFun) => (err, req, res, next) => {
//     Promise.resolve(theFun(req, res, next)).catch(next)
// }
// module.exports = CatchAsyncError;